<?xml version="1.0"?>
<robot name="myrobot_1">
    <material name="base_link_yellow">
        <color rgba="1 0.984 0 1"/>
    </material>
    <material name="top_link_red">
        <color rgba="1 0 0 1"/>
    </material>
    <link name="base_footprint"/>
    <link name="base_link">
        <visual>
            <geometry>
                <box size="0.6 0.4 0.2"/>
            </geometry>
            <origin xyz="0 0 0" rpy="0 0 0"/>
            <material name="base_link_yellow"/>
        </visual>
        <collision>
            <geometry>
                <box size="0.6 0.4 0.2" />
            </geometry>
            <origin xyz="0 0 0" rpy="0 0 0" />
        </collision>
        <inertial>
            <origin xyz="0 0 0.1" rpy="0 0 0" />
            <mass value="5" />
            <inertia ixx="0.083" ixy="0" ixz="0" iyy="0.167" iyz="0" izz="0.217" />
        </inertial>
    </link>
    <link name="left_wheel_link">
        <visual>
            <geometry>
                <cylinder radius="0.1" length="0.05"/>
            </geometry>
            <origin xyz="0 0.025 0" rpy="1.57079632679 0 0"/>
            <material name="top_link_red"/>
        </visual>
        <collision>
            <geometry>
                <cylinder radius="0.1" length="0.05"/>
            </geometry>
            <origin xyz="0 0.025 0" rpy="1.57079632679 0 0"/>
        </collision>
        <inertial>
            <origin xyz="0 0 0.1" rpy="0 0 0" />
            <mass value="1" />
            <inertia ixx="0.00271" ixy="0" ixz="0" iyy="0.00271" iyz="0" izz="0.005" />
        </inertial>
    </link>
    <link name="right_wheel_link">
        <visual>
            <geometry>
                <cylinder radius="0.1" length="0.05"/>
            </geometry>
            <origin xyz="0 -0.025 0" rpy="1.57079632679 0 0"/>
            <material name="top_link_red"/>
        </visual>
        <collision>
            <geometry>
                <cylinder radius="0.1" length="0.05"/>
            </geometry>
            <origin xyz="0 -0.025 0" rpy="1.57079632679 0 0"/>
        </collision>
        <inertial>
            <origin xyz="0 0 0.1" rpy="0 0 0" />
            <mass value="1" />
            <inertia ixx="0.00271" ixy="0" ixz="0" iyy="0.00271" iyz="0" izz="0.005" />
        </inertial>
    </link>
    <link name="caster_wheel_link">
        <visual>
            <geometry>
                <sphere radius="0.05"/>
            </geometry>
            <origin xyz="0 0 -0.05" rpy="0 0 0"/>
            <material name="top_link_red"/>
        </visual>
        <collision>
            <geometry>
                <sphere radius="0.05"/>
            </geometry>
            <origin xyz="0 0 -0.05" rpy="0 0 0"/>
        </collision>
        <inertial>
            <origin xyz="0 0 0.1" rpy="0 0 0" />
            <mass value="0.5" />
            <inertia ixx="0.0005" ixy="0" ixz="0" iyy="0.0005" iyz="0" izz="0.0005" />
        </inertial>
    </link>
    <joint name="base_joint" type="fixed">
        <parent link="base_footprint"/>
        <child link="base_link"/>
        <origin xyz="0 0 0.2" rpy="0 0 0"/>
        <axis xyz="0 0 0"/>
    </joint>
    <joint name="base_left_wheel_joint" type="continuous">
        <parent link="base_link"/>
        <child link="left_wheel_link"/>
        <origin xyz="-0.15 0.2 -0.1" rpy="0 0 0"/>
        <axis xyz="0 1 0"/>
    </joint>
    <joint name="base_right_wheel_joint" type="continuous">
        <parent link="base_link"/>
        <child link="right_wheel_link"/>
        <origin xyz="-0.15 -0.2 -0.1" rpy="0 0 0"/>
        <axis xyz="0 1 0"/>
    </joint>
    <joint name="base_caster_wheel_joint" type="fixed">
        <parent link="base_link"/>
        <child link="caster_wheel_link"/>
        <origin xyz="0.15 0 -0.1" rpy="0 0 0"/>
        <axis xyz="0 0 0"/>
    </joint>
</robot>